Ignoring exception in on_voice_state_update
Traceback (most recent call last):
  File "/home/pi/.local/lib/python3.10/site-packages/discord/client.py", line 343, in _run_event
    await coro(*args, **kwargs)
  File "/home/pi/jeffbot/JeffBOT/main.py", line 158, in on_voice_state_update
    stream_time_delta = time.time() - self.last_stream_time
NameError: name 'self' is not defined
